Traceback (most recent call last):
  File "/Users/didi/opt/anaconda3/envs/py3/lib/python3.8/site-packages/jupyter_cache/executors/utils.py", line 51, in single_nb_execution
    executenb(
  File "/Users/didi/opt/anaconda3/envs/py3/lib/python3.8/site-packages/nbclient/client.py", line 1112, in execute
    return NotebookClient(nb=nb, resources=resources, km=km, **kwargs).execute()
  File "/Users/didi/opt/anaconda3/envs/py3/lib/python3.8/site-packages/nbclient/util.py", line 74, in wrapped
    return just_run(coro(*args, **kwargs))
  File "/Users/didi/opt/anaconda3/envs/py3/lib/python3.8/site-packages/nbclient/util.py", line 53, in just_run
    return loop.run_until_complete(coro)
  File "/Users/didi/opt/anaconda3/envs/py3/lib/python3.8/asyncio/base_events.py", line 616, in run_until_complete
    return future.result()
  File "/Users/didi/opt/anaconda3/envs/py3/lib/python3.8/site-packages/nbclient/client.py", line 553, in async_execute
    await self.async_execute_cell(
  File "/Users/didi/opt/anaconda3/envs/py3/lib/python3.8/site-packages/nbclient/client.py", line 857, in async_execute_cell
    self._check_raise_for_error(cell, exec_reply)
  File "/Users/didi/opt/anaconda3/envs/py3/lib/python3.8/site-packages/nbclient/client.py", line 760, in _check_raise_for_error
    raise CellExecutionError.from_cell_and_msg(cell, exec_reply_content)
nbclient.exceptions.CellExecutionError: An error occurred while executing the following cell:
------------------
import numpy as np

print('Loading data ...')

data_root='./timit_11/'
train = np.load(data_root + 'train_11.npy')
train_label = np.load(data_root + 'train_label_11.npy')
test = np.load(data_root + 'test_11.npy')

print('Size of training data: {}'.format(train.shape))
print('Size of testing data: {}'.format(test.shape))
------------------

[0;31m---------------------------------------------------------------------------[0m
[0;31mFileNotFoundError[0m                         Traceback (most recent call last)
[0;32m<ipython-input-2-4de788cbfc0e>[0m in [0;36m<module>[0;34m[0m
[1;32m      4[0m [0;34m[0m[0m
[1;32m      5[0m [0mdata_root[0m[0;34m=[0m[0;34m'./timit_11/'[0m[0;34m[0m[0;34m[0m[0m
[0;32m----> 6[0;31m [0mtrain[0m [0;34m=[0m [0mnp[0m[0;34m.[0m[0mload[0m[0;34m([0m[0mdata_root[0m [0;34m+[0m [0;34m'train_11.npy'[0m[0;34m)[0m[0;34m[0m[0;34m[0m[0m
[0m[1;32m      7[0m [0mtrain_label[0m [0;34m=[0m [0mnp[0m[0;34m.[0m[0mload[0m[0;34m([0m[0mdata_root[0m [0;34m+[0m [0;34m'train_label_11.npy'[0m[0;34m)[0m[0;34m[0m[0;34m[0m[0m
[1;32m      8[0m [0mtest[0m [0;34m=[0m [0mnp[0m[0;34m.[0m[0mload[0m[0;34m([0m[0mdata_root[0m [0;34m+[0m [0;34m'test_11.npy'[0m[0;34m)[0m[0;34m[0m[0;34m[0m[0m

[0;32m~/opt/anaconda3/envs/py3/lib/python3.8/site-packages/numpy/lib/npyio.py[0m in [0;36mload[0;34m(file, mmap_mode, allow_pickle, fix_imports, encoding)[0m
[1;32m    426[0m         [0mown_fid[0m [0;34m=[0m [0;32mFalse[0m[0;34m[0m[0;34m[0m[0m
[1;32m    427[0m     [0;32melse[0m[0;34m:[0m[0;34m[0m[0;34m[0m[0m
[0;32m--> 428[0;31m         [0mfid[0m [0;34m=[0m [0mopen[0m[0;34m([0m[0mos_fspath[0m[0;34m([0m[0mfile[0m[0;34m)[0m[0;34m,[0m [0;34m"rb"[0m[0;34m)[0m[0;34m[0m[0;34m[0m[0m
[0m[1;32m    429[0m         [0mown_fid[0m [0;34m=[0m [0;32mTrue[0m[0;34m[0m[0;34m[0m[0m
[1;32m    430[0m [0;34m[0m[0m

[0;31mFileNotFoundError[0m: [Errno 2] No such file or directory: './timit_11/train_11.npy'
FileNotFoundError: [Errno 2] No such file or directory: './timit_11/train_11.npy'

